[2023-12-21T13:37:06.906+0000] {logging_mixin.py:154} INFO - Changing /opt/***/logs/dag_id=scraping-jobs/run_id=manual__2023-12-21T13:23:03.607351+00:00/task_id=test*** permission to 509
[2023-12-21T13:37:06.913+0000] {logging_mixin.py:154} INFO - Failed to change /opt/***/logs/dag_id=scraping-jobs/run_id=manual__2023-12-21T13:23:03.607351+00:00/task_id=test*** permission to 509: [Errno 1] Operation not permitted: '/opt/***/logs/dag_id=scraping-jobs/run_id=manual__2023-12-21T13:23:03.607351+00:00/task_id=test***'
[2023-12-21T13:37:06.997+0000] {logging_mixin.py:154} INFO - Changing /opt/***/logs/dag_id=scraping-jobs/run_id=manual__2023-12-21T13:23:03.607351+00:00/task_id=test*** permission to 509
[2023-12-21T13:37:06.999+0000] {logging_mixin.py:154} INFO - Failed to change /opt/***/logs/dag_id=scraping-jobs/run_id=manual__2023-12-21T13:23:03.607351+00:00/task_id=test*** permission to 509: [Errno 1] Operation not permitted: '/opt/***/logs/dag_id=scraping-jobs/run_id=manual__2023-12-21T13:23:03.607351+00:00/task_id=test***'
[2023-12-21T13:37:07.178+0000] {taskinstance.py:1159} INFO - Dependencies all met for dep_context=non-requeueable deps ti=<TaskInstance: scraping-jobs.testairflow manual__2023-12-21T13:23:03.607351+00:00 [queued]>
[2023-12-21T13:37:07.206+0000] {taskinstance.py:1159} INFO - Dependencies all met for dep_context=requeueable deps ti=<TaskInstance: scraping-jobs.testairflow manual__2023-12-21T13:23:03.607351+00:00 [queued]>
[2023-12-21T13:37:07.207+0000] {taskinstance.py:1361} INFO - Starting attempt 2 of 2
[2023-12-21T13:37:07.245+0000] {taskinstance.py:1382} INFO - Executing <Task(BashOperator): testairflow> on 2023-12-21 13:23:03.607351+00:00
[2023-12-21T13:37:07.255+0000] {standard_task_runner.py:57} INFO - Started process 400 to run task
[2023-12-21T13:37:07.259+0000] {standard_task_runner.py:84} INFO - Running: ['***', 'tasks', 'run', 'scraping-jobs', 'test***', 'manual__2023-12-21T13:23:03.607351+00:00', '--job-id', '11', '--raw', '--subdir', 'DAGS_FOLDER/dag-webscrappinglinkedin.py', '--cfg-path', '/tmp/tmpo9t1qat1']
[2023-12-21T13:37:07.262+0000] {standard_task_runner.py:85} INFO - Job 11: Subtask test***
[2023-12-21T13:37:07.345+0000] {logging_mixin.py:154} INFO - Changing /opt/***/logs/dag_id=scraping-jobs/run_id=manual__2023-12-21T13:23:03.607351+00:00/task_id=test*** permission to 509
[2023-12-21T13:37:07.346+0000] {logging_mixin.py:154} INFO - Failed to change /opt/***/logs/dag_id=scraping-jobs/run_id=manual__2023-12-21T13:23:03.607351+00:00/task_id=test*** permission to 509: [Errno 1] Operation not permitted: '/opt/***/logs/dag_id=scraping-jobs/run_id=manual__2023-12-21T13:23:03.607351+00:00/task_id=test***'
[2023-12-21T13:37:07.351+0000] {task_command.py:416} INFO - Running <TaskInstance: scraping-jobs.testairflow manual__2023-12-21T13:23:03.607351+00:00 [running]> on host ae1e32dc581d
[2023-12-21T13:37:07.514+0000] {taskinstance.py:1662} INFO - Exporting env vars: AIRFLOW_CTX_DAG_OWNER='***' AIRFLOW_CTX_DAG_ID='scraping-jobs' AIRFLOW_CTX_TASK_ID='test***' AIRFLOW_CTX_EXECUTION_DATE='2023-12-21T13:23:03.607351+00:00' AIRFLOW_CTX_TRY_NUMBER='2' AIRFLOW_CTX_DAG_RUN_ID='manual__2023-12-21T13:23:03.607351+00:00'
[2023-12-21T13:37:07.524+0000] {subprocess.py:63} INFO - Tmp dir root location: /tmp
[2023-12-21T13:37:07.530+0000] {subprocess.py:75} INFO - Running command: ['/bin/bash', '-c', 'python /opt/***/dags/apps/crawler.py']
[2023-12-21T13:37:07.562+0000] {subprocess.py:86} INFO - Output:
[2023-12-21T13:37:14.190+0000] {subprocess.py:93} INFO - Traceback (most recent call last):
[2023-12-21T13:37:14.192+0000] {subprocess.py:93} INFO -   File "/home/***/.local/lib/python3.8/site-packages/urllib3/connection.py", line 174, in _new_conn
[2023-12-21T13:37:14.194+0000] {subprocess.py:93} INFO -     conn = connection.create_connection(
[2023-12-21T13:37:14.195+0000] {subprocess.py:93} INFO -   File "/home/***/.local/lib/python3.8/site-packages/urllib3/util/connection.py", line 72, in create_connection
[2023-12-21T13:37:14.200+0000] {subprocess.py:93} INFO -     for res in socket.getaddrinfo(host, port, family, socket.SOCK_STREAM):
[2023-12-21T13:37:14.207+0000] {subprocess.py:93} INFO -   File "/usr/local/lib/python3.8/socket.py", line 918, in getaddrinfo
[2023-12-21T13:37:14.210+0000] {subprocess.py:93} INFO -     for res in _socket.getaddrinfo(host, port, family, type, proto, flags):
[2023-12-21T13:37:14.211+0000] {subprocess.py:93} INFO - socket.gaierror: [Errno -2] Name or service not known
[2023-12-21T13:37:14.217+0000] {subprocess.py:93} INFO - 
[2023-12-21T13:37:14.219+0000] {subprocess.py:93} INFO - During handling of the above exception, another exception occurred:
[2023-12-21T13:37:14.220+0000] {subprocess.py:93} INFO - 
[2023-12-21T13:37:14.222+0000] {subprocess.py:93} INFO - Traceback (most recent call last):
[2023-12-21T13:37:14.224+0000] {subprocess.py:93} INFO -   File "/home/***/.local/lib/python3.8/site-packages/urllib3/connectionpool.py", line 715, in urlopen
[2023-12-21T13:37:14.232+0000] {subprocess.py:93} INFO -     httplib_response = self._make_request(
[2023-12-21T13:37:14.234+0000] {subprocess.py:93} INFO -   File "/home/***/.local/lib/python3.8/site-packages/urllib3/connectionpool.py", line 416, in _make_request
[2023-12-21T13:37:14.235+0000] {subprocess.py:93} INFO -     conn.request(method, url, **httplib_request_kw)
[2023-12-21T13:37:14.236+0000] {subprocess.py:93} INFO -   File "/home/***/.local/lib/python3.8/site-packages/urllib3/connection.py", line 244, in request
[2023-12-21T13:37:14.238+0000] {subprocess.py:93} INFO -     super(HTTPConnection, self).request(method, url, body=body, headers=headers)
[2023-12-21T13:37:14.240+0000] {subprocess.py:93} INFO -   File "/usr/local/lib/python3.8/http/client.py", line 1256, in request
[2023-12-21T13:37:14.242+0000] {subprocess.py:93} INFO -     self._send_request(method, url, body, headers, encode_chunked)
[2023-12-21T13:37:14.245+0000] {subprocess.py:93} INFO -   File "/usr/local/lib/python3.8/http/client.py", line 1302, in _send_request
[2023-12-21T13:37:14.250+0000] {subprocess.py:93} INFO -     self.endheaders(body, encode_chunked=encode_chunked)
[2023-12-21T13:37:14.251+0000] {subprocess.py:93} INFO -   File "/usr/local/lib/python3.8/http/client.py", line 1251, in endheaders
[2023-12-21T13:37:14.253+0000] {subprocess.py:93} INFO -     self._send_output(message_body, encode_chunked=encode_chunked)
[2023-12-21T13:37:14.255+0000] {subprocess.py:93} INFO -   File "/usr/local/lib/python3.8/http/client.py", line 1011, in _send_output
[2023-12-21T13:37:14.257+0000] {subprocess.py:93} INFO -     self.send(msg)
[2023-12-21T13:37:14.258+0000] {subprocess.py:93} INFO -   File "/usr/local/lib/python3.8/http/client.py", line 951, in send
[2023-12-21T13:37:14.259+0000] {subprocess.py:93} INFO -     self.connect()
[2023-12-21T13:37:14.260+0000] {subprocess.py:93} INFO -   File "/home/***/.local/lib/python3.8/site-packages/urllib3/connection.py", line 205, in connect
[2023-12-21T13:37:14.261+0000] {subprocess.py:93} INFO -     conn = self._new_conn()
[2023-12-21T13:37:14.263+0000] {subprocess.py:93} INFO -   File "/home/***/.local/lib/python3.8/site-packages/urllib3/connection.py", line 186, in _new_conn
[2023-12-21T13:37:14.266+0000] {subprocess.py:93} INFO -     raise NewConnectionError(
[2023-12-21T13:37:14.268+0000] {subprocess.py:93} INFO - urllib3.exceptions.NewConnectionError: <urllib3.connection.HTTPConnection object at 0x7fdc2dffb4f0>: Failed to establish a new connection: [Errno -2] Name or service not known
[2023-12-21T13:37:14.271+0000] {subprocess.py:93} INFO - 
[2023-12-21T13:37:14.273+0000] {subprocess.py:93} INFO - During handling of the above exception, another exception occurred:
[2023-12-21T13:37:14.274+0000] {subprocess.py:93} INFO - 
[2023-12-21T13:37:14.275+0000] {subprocess.py:93} INFO - Traceback (most recent call last):
[2023-12-21T13:37:14.277+0000] {subprocess.py:93} INFO -   File "/opt/***/dags/apps/crawler.py", line 31, in <module>
[2023-12-21T13:37:14.279+0000] {subprocess.py:93} INFO -     with webdriver.Remote(f'{remote_webdriver}:4444/wd/hub', options=browser_options) as driver:
[2023-12-21T13:37:14.283+0000] {subprocess.py:93} INFO -   File "/home/***/.local/lib/python3.8/site-packages/selenium/webdriver/remote/webdriver.py", line 208, in __init__
[2023-12-21T13:37:14.284+0000] {subprocess.py:93} INFO -     self.start_session(capabilities)
[2023-12-21T13:37:14.285+0000] {subprocess.py:93} INFO -   File "/home/***/.local/lib/python3.8/site-packages/selenium/webdriver/remote/webdriver.py", line 292, in start_session
[2023-12-21T13:37:14.286+0000] {subprocess.py:93} INFO -     response = self.execute(Command.NEW_SESSION, caps)["value"]
[2023-12-21T13:37:14.287+0000] {subprocess.py:93} INFO -   File "/home/***/.local/lib/python3.8/site-packages/selenium/webdriver/remote/webdriver.py", line 345, in execute
[2023-12-21T13:37:14.289+0000] {subprocess.py:93} INFO -     response = self.command_executor.execute(driver_command, params)
[2023-12-21T13:37:14.290+0000] {subprocess.py:93} INFO -   File "/home/***/.local/lib/python3.8/site-packages/selenium/webdriver/remote/remote_connection.py", line 300, in execute
[2023-12-21T13:37:14.292+0000] {subprocess.py:93} INFO -     return self._request(command_info[0], url, body=data)
[2023-12-21T13:37:14.292+0000] {subprocess.py:93} INFO -   File "/home/***/.local/lib/python3.8/site-packages/selenium/webdriver/remote/remote_connection.py", line 321, in _request
[2023-12-21T13:37:14.293+0000] {subprocess.py:93} INFO -     response = self._conn.request(method, url, body=body, headers=headers)
[2023-12-21T13:37:14.294+0000] {subprocess.py:93} INFO -   File "/home/***/.local/lib/python3.8/site-packages/urllib3/request.py", line 81, in request
[2023-12-21T13:37:14.295+0000] {subprocess.py:93} INFO -     return self.request_encode_body(
[2023-12-21T13:37:14.296+0000] {subprocess.py:93} INFO -   File "/home/***/.local/lib/python3.8/site-packages/urllib3/request.py", line 173, in request_encode_body
[2023-12-21T13:37:14.297+0000] {subprocess.py:93} INFO -     return self.urlopen(method, url, **extra_kw)
[2023-12-21T13:37:14.299+0000] {subprocess.py:93} INFO -   File "/home/***/.local/lib/python3.8/site-packages/urllib3/poolmanager.py", line 376, in urlopen
[2023-12-21T13:37:14.300+0000] {subprocess.py:93} INFO -     response = conn.urlopen(method, u.request_uri, **kw)
[2023-12-21T13:37:14.301+0000] {subprocess.py:93} INFO -   File "/home/***/.local/lib/python3.8/site-packages/urllib3/connectionpool.py", line 827, in urlopen
[2023-12-21T13:37:14.302+0000] {subprocess.py:93} INFO -     return self.urlopen(
[2023-12-21T13:37:14.303+0000] {subprocess.py:93} INFO -   File "/home/***/.local/lib/python3.8/site-packages/urllib3/connectionpool.py", line 827, in urlopen
[2023-12-21T13:37:14.304+0000] {subprocess.py:93} INFO -     return self.urlopen(
[2023-12-21T13:37:14.305+0000] {subprocess.py:93} INFO -   File "/home/***/.local/lib/python3.8/site-packages/urllib3/connectionpool.py", line 827, in urlopen
[2023-12-21T13:37:14.306+0000] {subprocess.py:93} INFO -     return self.urlopen(
[2023-12-21T13:37:14.307+0000] {subprocess.py:93} INFO -   File "/home/***/.local/lib/python3.8/site-packages/urllib3/connectionpool.py", line 799, in urlopen
[2023-12-21T13:37:14.308+0000] {subprocess.py:93} INFO -     retries = retries.increment(
[2023-12-21T13:37:14.309+0000] {subprocess.py:93} INFO -   File "/home/***/.local/lib/python3.8/site-packages/urllib3/util/retry.py", line 592, in increment
[2023-12-21T13:37:14.310+0000] {subprocess.py:93} INFO -     raise MaxRetryError(_pool, url, error or ResponseError(cause))
[2023-12-21T13:37:14.310+0000] {subprocess.py:93} INFO - urllib3.exceptions.MaxRetryError: HTTPConnectionPool(host='remote_chromedriver', port=4444): Max retries exceeded with url: /wd/hub/session (Caused by NewConnectionError('<urllib3.connection.HTTPConnection object at 0x7fdc2dffb4f0>: Failed to establish a new connection: [Errno -2] Name or service not known'))
[2023-12-21T13:37:14.312+0000] {subprocess.py:97} INFO - Command exited with return code 1
[2023-12-21T13:37:14.337+0000] {taskinstance.py:1937} ERROR - Task failed with exception
Traceback (most recent call last):
  File "/home/airflow/.local/lib/python3.8/site-packages/airflow/operators/bash.py", line 210, in execute
    raise AirflowException(
airflow.exceptions.AirflowException: Bash command failed. The command returned a non-zero exit code 1.
[2023-12-21T13:37:14.347+0000] {taskinstance.py:1400} INFO - Marking task as FAILED. dag_id=scraping-jobs, task_id=test***, execution_date=20231221T132303, start_date=20231221T133707, end_date=20231221T133714
[2023-12-21T13:37:14.384+0000] {standard_task_runner.py:104} ERROR - Failed to execute job 11 for task test*** (Bash command failed. The command returned a non-zero exit code 1.; 400)
[2023-12-21T13:37:14.422+0000] {local_task_job_runner.py:228} INFO - Task exited with return code 1
[2023-12-21T13:37:14.457+0000] {taskinstance.py:2778} INFO - 0 downstream tasks scheduled from follow-on schedule check
