[2023-12-21T13:41:42.507+0000] {logging_mixin.py:154} INFO - Changing /opt/***/logs/dag_id=scraping-jobs/run_id=manual__2023-12-21T13:23:03.607351+00:00/task_id=test*** permission to 509
[2023-12-21T13:41:42.509+0000] {logging_mixin.py:154} INFO - Failed to change /opt/***/logs/dag_id=scraping-jobs/run_id=manual__2023-12-21T13:23:03.607351+00:00/task_id=test*** permission to 509: [Errno 1] Operation not permitted: '/opt/***/logs/dag_id=scraping-jobs/run_id=manual__2023-12-21T13:23:03.607351+00:00/task_id=test***'
[2023-12-21T13:41:42.558+0000] {logging_mixin.py:154} INFO - Changing /opt/***/logs/dag_id=scraping-jobs/run_id=manual__2023-12-21T13:23:03.607351+00:00/task_id=test*** permission to 509
[2023-12-21T13:41:42.665+0000] {logging_mixin.py:154} INFO - Failed to change /opt/***/logs/dag_id=scraping-jobs/run_id=manual__2023-12-21T13:23:03.607351+00:00/task_id=test*** permission to 509: [Errno 1] Operation not permitted: '/opt/***/logs/dag_id=scraping-jobs/run_id=manual__2023-12-21T13:23:03.607351+00:00/task_id=test***'
[2023-12-21T13:41:42.743+0000] {taskinstance.py:1159} INFO - Dependencies all met for dep_context=non-requeueable deps ti=<TaskInstance: scraping-jobs.testairflow manual__2023-12-21T13:23:03.607351+00:00 [queued]>
[2023-12-21T13:41:42.760+0000] {taskinstance.py:1159} INFO - Dependencies all met for dep_context=requeueable deps ti=<TaskInstance: scraping-jobs.testairflow manual__2023-12-21T13:23:03.607351+00:00 [queued]>
[2023-12-21T13:41:42.762+0000] {taskinstance.py:1361} INFO - Starting attempt 3 of 3
[2023-12-21T13:41:42.791+0000] {taskinstance.py:1382} INFO - Executing <Task(BashOperator): testairflow> on 2023-12-21 13:23:03.607351+00:00
[2023-12-21T13:41:42.801+0000] {standard_task_runner.py:57} INFO - Started process 461 to run task
[2023-12-21T13:41:42.808+0000] {standard_task_runner.py:84} INFO - Running: ['***', 'tasks', 'run', 'scraping-jobs', 'test***', 'manual__2023-12-21T13:23:03.607351+00:00', '--job-id', '12', '--raw', '--subdir', 'DAGS_FOLDER/dag-webscrappinglinkedin.py', '--cfg-path', '/tmp/tmpleb2wpob']
[2023-12-21T13:41:42.812+0000] {standard_task_runner.py:85} INFO - Job 12: Subtask test***
[2023-12-21T13:41:42.916+0000] {logging_mixin.py:154} INFO - Changing /opt/***/logs/dag_id=scraping-jobs/run_id=manual__2023-12-21T13:23:03.607351+00:00/task_id=test*** permission to 509
[2023-12-21T13:41:42.918+0000] {logging_mixin.py:154} INFO - Failed to change /opt/***/logs/dag_id=scraping-jobs/run_id=manual__2023-12-21T13:23:03.607351+00:00/task_id=test*** permission to 509: [Errno 1] Operation not permitted: '/opt/***/logs/dag_id=scraping-jobs/run_id=manual__2023-12-21T13:23:03.607351+00:00/task_id=test***'
[2023-12-21T13:41:42.924+0000] {task_command.py:416} INFO - Running <TaskInstance: scraping-jobs.testairflow manual__2023-12-21T13:23:03.607351+00:00 [running]> on host ae1e32dc581d
[2023-12-21T13:41:43.089+0000] {taskinstance.py:1662} INFO - Exporting env vars: AIRFLOW_CTX_DAG_OWNER='***' AIRFLOW_CTX_DAG_ID='scraping-jobs' AIRFLOW_CTX_TASK_ID='test***' AIRFLOW_CTX_EXECUTION_DATE='2023-12-21T13:23:03.607351+00:00' AIRFLOW_CTX_TRY_NUMBER='3' AIRFLOW_CTX_DAG_RUN_ID='manual__2023-12-21T13:23:03.607351+00:00'
[2023-12-21T13:41:43.094+0000] {subprocess.py:63} INFO - Tmp dir root location: /tmp
[2023-12-21T13:41:43.099+0000] {subprocess.py:75} INFO - Running command: ['/bin/bash', '-c', 'python /opt/***/dags/apps/crawler.py']
[2023-12-21T13:41:43.120+0000] {subprocess.py:86} INFO - Output:
[2023-12-21T13:41:49.175+0000] {subprocess.py:93} INFO - Traceback (most recent call last):
[2023-12-21T13:41:49.177+0000] {subprocess.py:93} INFO -   File "/home/***/.local/lib/python3.8/site-packages/urllib3/connection.py", line 174, in _new_conn
[2023-12-21T13:41:49.178+0000] {subprocess.py:93} INFO -     conn = connection.create_connection(
[2023-12-21T13:41:49.179+0000] {subprocess.py:93} INFO -   File "/home/***/.local/lib/python3.8/site-packages/urllib3/util/connection.py", line 72, in create_connection
[2023-12-21T13:41:49.181+0000] {subprocess.py:93} INFO -     for res in socket.getaddrinfo(host, port, family, socket.SOCK_STREAM):
[2023-12-21T13:41:49.182+0000] {subprocess.py:93} INFO -   File "/usr/local/lib/python3.8/socket.py", line 918, in getaddrinfo
[2023-12-21T13:41:49.183+0000] {subprocess.py:93} INFO -     for res in _socket.getaddrinfo(host, port, family, type, proto, flags):
[2023-12-21T13:41:49.184+0000] {subprocess.py:93} INFO - socket.gaierror: [Errno -2] Name or service not known
[2023-12-21T13:41:49.185+0000] {subprocess.py:93} INFO - 
[2023-12-21T13:41:49.187+0000] {subprocess.py:93} INFO - During handling of the above exception, another exception occurred:
[2023-12-21T13:41:49.188+0000] {subprocess.py:93} INFO - 
[2023-12-21T13:41:49.189+0000] {subprocess.py:93} INFO - Traceback (most recent call last):
[2023-12-21T13:41:49.191+0000] {subprocess.py:93} INFO -   File "/home/***/.local/lib/python3.8/site-packages/urllib3/connectionpool.py", line 715, in urlopen
[2023-12-21T13:41:49.192+0000] {subprocess.py:93} INFO -     httplib_response = self._make_request(
[2023-12-21T13:41:49.193+0000] {subprocess.py:93} INFO -   File "/home/***/.local/lib/python3.8/site-packages/urllib3/connectionpool.py", line 416, in _make_request
[2023-12-21T13:41:49.194+0000] {subprocess.py:93} INFO -     conn.request(method, url, **httplib_request_kw)
[2023-12-21T13:41:49.195+0000] {subprocess.py:93} INFO -   File "/home/***/.local/lib/python3.8/site-packages/urllib3/connection.py", line 244, in request
[2023-12-21T13:41:49.196+0000] {subprocess.py:93} INFO -     super(HTTPConnection, self).request(method, url, body=body, headers=headers)
[2023-12-21T13:41:49.197+0000] {subprocess.py:93} INFO -   File "/usr/local/lib/python3.8/http/client.py", line 1256, in request
[2023-12-21T13:41:49.197+0000] {subprocess.py:93} INFO -     self._send_request(method, url, body, headers, encode_chunked)
[2023-12-21T13:41:49.198+0000] {subprocess.py:93} INFO -   File "/usr/local/lib/python3.8/http/client.py", line 1302, in _send_request
[2023-12-21T13:41:49.199+0000] {subprocess.py:93} INFO -     self.endheaders(body, encode_chunked=encode_chunked)
[2023-12-21T13:41:49.201+0000] {subprocess.py:93} INFO -   File "/usr/local/lib/python3.8/http/client.py", line 1251, in endheaders
[2023-12-21T13:41:49.202+0000] {subprocess.py:93} INFO -     self._send_output(message_body, encode_chunked=encode_chunked)
[2023-12-21T13:41:49.203+0000] {subprocess.py:93} INFO -   File "/usr/local/lib/python3.8/http/client.py", line 1011, in _send_output
[2023-12-21T13:41:49.204+0000] {subprocess.py:93} INFO -     self.send(msg)
[2023-12-21T13:41:49.206+0000] {subprocess.py:93} INFO -   File "/usr/local/lib/python3.8/http/client.py", line 951, in send
[2023-12-21T13:41:49.207+0000] {subprocess.py:93} INFO -     self.connect()
[2023-12-21T13:41:49.208+0000] {subprocess.py:93} INFO -   File "/home/***/.local/lib/python3.8/site-packages/urllib3/connection.py", line 205, in connect
[2023-12-21T13:41:49.210+0000] {subprocess.py:93} INFO -     conn = self._new_conn()
[2023-12-21T13:41:49.211+0000] {subprocess.py:93} INFO -   File "/home/***/.local/lib/python3.8/site-packages/urllib3/connection.py", line 186, in _new_conn
[2023-12-21T13:41:49.212+0000] {subprocess.py:93} INFO -     raise NewConnectionError(
[2023-12-21T13:41:49.213+0000] {subprocess.py:93} INFO - urllib3.exceptions.NewConnectionError: <urllib3.connection.HTTPConnection object at 0x7f341a0c47f0>: Failed to establish a new connection: [Errno -2] Name or service not known
[2023-12-21T13:41:49.214+0000] {subprocess.py:93} INFO - 
[2023-12-21T13:41:49.215+0000] {subprocess.py:93} INFO - During handling of the above exception, another exception occurred:
[2023-12-21T13:41:49.216+0000] {subprocess.py:93} INFO - 
[2023-12-21T13:41:49.217+0000] {subprocess.py:93} INFO - Traceback (most recent call last):
[2023-12-21T13:41:49.218+0000] {subprocess.py:93} INFO -   File "/opt/***/dags/apps/crawler.py", line 31, in <module>
[2023-12-21T13:41:49.219+0000] {subprocess.py:93} INFO -     with webdriver.Remote(f'{remote_webdriver}:4444/wd/hub', options=browser_options) as driver:
[2023-12-21T13:41:49.220+0000] {subprocess.py:93} INFO -   File "/home/***/.local/lib/python3.8/site-packages/selenium/webdriver/remote/webdriver.py", line 208, in __init__
[2023-12-21T13:41:49.222+0000] {subprocess.py:93} INFO -     self.start_session(capabilities)
[2023-12-21T13:41:49.223+0000] {subprocess.py:93} INFO -   File "/home/***/.local/lib/python3.8/site-packages/selenium/webdriver/remote/webdriver.py", line 292, in start_session
[2023-12-21T13:41:49.224+0000] {subprocess.py:93} INFO -     response = self.execute(Command.NEW_SESSION, caps)["value"]
[2023-12-21T13:41:49.225+0000] {subprocess.py:93} INFO -   File "/home/***/.local/lib/python3.8/site-packages/selenium/webdriver/remote/webdriver.py", line 345, in execute
[2023-12-21T13:41:49.226+0000] {subprocess.py:93} INFO -     response = self.command_executor.execute(driver_command, params)
[2023-12-21T13:41:49.228+0000] {subprocess.py:93} INFO -   File "/home/***/.local/lib/python3.8/site-packages/selenium/webdriver/remote/remote_connection.py", line 300, in execute
[2023-12-21T13:41:49.229+0000] {subprocess.py:93} INFO -     return self._request(command_info[0], url, body=data)
[2023-12-21T13:41:49.230+0000] {subprocess.py:93} INFO -   File "/home/***/.local/lib/python3.8/site-packages/selenium/webdriver/remote/remote_connection.py", line 321, in _request
[2023-12-21T13:41:49.231+0000] {subprocess.py:93} INFO -     response = self._conn.request(method, url, body=body, headers=headers)
[2023-12-21T13:41:49.232+0000] {subprocess.py:93} INFO -   File "/home/***/.local/lib/python3.8/site-packages/urllib3/request.py", line 81, in request
[2023-12-21T13:41:49.233+0000] {subprocess.py:93} INFO -     return self.request_encode_body(
[2023-12-21T13:41:49.234+0000] {subprocess.py:93} INFO -   File "/home/***/.local/lib/python3.8/site-packages/urllib3/request.py", line 173, in request_encode_body
[2023-12-21T13:41:49.235+0000] {subprocess.py:93} INFO -     return self.urlopen(method, url, **extra_kw)
[2023-12-21T13:41:49.237+0000] {subprocess.py:93} INFO -   File "/home/***/.local/lib/python3.8/site-packages/urllib3/poolmanager.py", line 376, in urlopen
[2023-12-21T13:41:49.238+0000] {subprocess.py:93} INFO -     response = conn.urlopen(method, u.request_uri, **kw)
[2023-12-21T13:41:49.239+0000] {subprocess.py:93} INFO -   File "/home/***/.local/lib/python3.8/site-packages/urllib3/connectionpool.py", line 827, in urlopen
[2023-12-21T13:41:49.240+0000] {subprocess.py:93} INFO -     return self.urlopen(
[2023-12-21T13:41:49.241+0000] {subprocess.py:93} INFO -   File "/home/***/.local/lib/python3.8/site-packages/urllib3/connectionpool.py", line 827, in urlopen
[2023-12-21T13:41:49.242+0000] {subprocess.py:93} INFO -     return self.urlopen(
[2023-12-21T13:41:49.243+0000] {subprocess.py:93} INFO -   File "/home/***/.local/lib/python3.8/site-packages/urllib3/connectionpool.py", line 827, in urlopen
[2023-12-21T13:41:49.244+0000] {subprocess.py:93} INFO -     return self.urlopen(
[2023-12-21T13:41:49.245+0000] {subprocess.py:93} INFO -   File "/home/***/.local/lib/python3.8/site-packages/urllib3/connectionpool.py", line 799, in urlopen
[2023-12-21T13:41:49.246+0000] {subprocess.py:93} INFO -     retries = retries.increment(
[2023-12-21T13:41:49.247+0000] {subprocess.py:93} INFO -   File "/home/***/.local/lib/python3.8/site-packages/urllib3/util/retry.py", line 592, in increment
[2023-12-21T13:41:49.247+0000] {subprocess.py:93} INFO -     raise MaxRetryError(_pool, url, error or ResponseError(cause))
[2023-12-21T13:41:49.248+0000] {subprocess.py:93} INFO - urllib3.exceptions.MaxRetryError: HTTPConnectionPool(host='remote_chromedriver', port=4444): Max retries exceeded with url: /wd/hub/session (Caused by NewConnectionError('<urllib3.connection.HTTPConnection object at 0x7f341a0c47f0>: Failed to establish a new connection: [Errno -2] Name or service not known'))
[2023-12-21T13:41:49.254+0000] {subprocess.py:97} INFO - Command exited with return code 1
[2023-12-21T13:41:49.270+0000] {taskinstance.py:1937} ERROR - Task failed with exception
Traceback (most recent call last):
  File "/home/airflow/.local/lib/python3.8/site-packages/airflow/operators/bash.py", line 210, in execute
    raise AirflowException(
airflow.exceptions.AirflowException: Bash command failed. The command returned a non-zero exit code 1.
[2023-12-21T13:41:49.276+0000] {taskinstance.py:1400} INFO - Marking task as FAILED. dag_id=scraping-jobs, task_id=test***, execution_date=20231221T132303, start_date=20231221T134142, end_date=20231221T134149
[2023-12-21T13:41:49.297+0000] {standard_task_runner.py:104} ERROR - Failed to execute job 12 for task test*** (Bash command failed. The command returned a non-zero exit code 1.; 461)
[2023-12-21T13:41:49.328+0000] {local_task_job_runner.py:228} INFO - Task exited with return code 1
[2023-12-21T13:41:49.352+0000] {taskinstance.py:2778} INFO - 0 downstream tasks scheduled from follow-on schedule check
