[2023-12-21T14:46:42.002+0000] {logging_mixin.py:154} INFO - Changing /opt/***/logs/dag_id=scraping-jobs/run_id=manual__2023-12-21T14:46:35.759727+00:00/task_id=test*** permission to 509
[2023-12-21T14:46:42.019+0000] {logging_mixin.py:154} INFO - Failed to change /opt/***/logs/dag_id=scraping-jobs/run_id=manual__2023-12-21T14:46:35.759727+00:00/task_id=test*** permission to 509: [Errno 1] Operation not permitted: '/opt/***/logs/dag_id=scraping-jobs/run_id=manual__2023-12-21T14:46:35.759727+00:00/task_id=test***'
[2023-12-21T14:46:42.225+0000] {logging_mixin.py:154} INFO - Changing /opt/***/logs/dag_id=scraping-jobs/run_id=manual__2023-12-21T14:46:35.759727+00:00/task_id=test*** permission to 509
[2023-12-21T14:46:42.226+0000] {logging_mixin.py:154} INFO - Failed to change /opt/***/logs/dag_id=scraping-jobs/run_id=manual__2023-12-21T14:46:35.759727+00:00/task_id=test*** permission to 509: [Errno 1] Operation not permitted: '/opt/***/logs/dag_id=scraping-jobs/run_id=manual__2023-12-21T14:46:35.759727+00:00/task_id=test***'
[2023-12-21T14:46:42.450+0000] {taskinstance.py:1159} INFO - Dependencies all met for dep_context=non-requeueable deps ti=<TaskInstance: scraping-jobs.testairflow manual__2023-12-21T14:46:35.759727+00:00 [queued]>
[2023-12-21T14:46:42.519+0000] {taskinstance.py:1159} INFO - Dependencies all met for dep_context=requeueable deps ti=<TaskInstance: scraping-jobs.testairflow manual__2023-12-21T14:46:35.759727+00:00 [queued]>
[2023-12-21T14:46:42.521+0000] {taskinstance.py:1361} INFO - Starting attempt 1 of 1
[2023-12-21T14:46:42.614+0000] {taskinstance.py:1382} INFO - Executing <Task(BashOperator): testairflow> on 2023-12-21 14:46:35.759727+00:00
[2023-12-21T14:46:42.673+0000] {standard_task_runner.py:57} INFO - Started process 687 to run task
[2023-12-21T14:46:42.680+0000] {standard_task_runner.py:84} INFO - Running: ['***', 'tasks', 'run', 'scraping-jobs', 'test***', 'manual__2023-12-21T14:46:35.759727+00:00', '--job-id', '23', '--raw', '--subdir', 'DAGS_FOLDER/dag-webscrappinglinkedin.py', '--cfg-path', '/tmp/tmpedmmetrm']
[2023-12-21T14:46:42.707+0000] {standard_task_runner.py:85} INFO - Job 23: Subtask test***
[2023-12-21T14:46:42.926+0000] {logging_mixin.py:154} INFO - Changing /opt/***/logs/dag_id=scraping-jobs/run_id=manual__2023-12-21T14:46:35.759727+00:00/task_id=test*** permission to 509
[2023-12-21T14:46:42.937+0000] {logging_mixin.py:154} INFO - Failed to change /opt/***/logs/dag_id=scraping-jobs/run_id=manual__2023-12-21T14:46:35.759727+00:00/task_id=test*** permission to 509: [Errno 1] Operation not permitted: '/opt/***/logs/dag_id=scraping-jobs/run_id=manual__2023-12-21T14:46:35.759727+00:00/task_id=test***'
[2023-12-21T14:46:42.957+0000] {task_command.py:416} INFO - Running <TaskInstance: scraping-jobs.testairflow manual__2023-12-21T14:46:35.759727+00:00 [running]> on host ae1e32dc581d
[2023-12-21T14:46:43.401+0000] {taskinstance.py:1662} INFO - Exporting env vars: AIRFLOW_CTX_DAG_OWNER='***' AIRFLOW_CTX_DAG_ID='scraping-jobs' AIRFLOW_CTX_TASK_ID='test***' AIRFLOW_CTX_EXECUTION_DATE='2023-12-21T14:46:35.759727+00:00' AIRFLOW_CTX_TRY_NUMBER='1' AIRFLOW_CTX_DAG_RUN_ID='manual__2023-12-21T14:46:35.759727+00:00'
[2023-12-21T14:46:43.415+0000] {subprocess.py:63} INFO - Tmp dir root location: /tmp
[2023-12-21T14:46:43.440+0000] {subprocess.py:75} INFO - Running command: ['/bin/bash', '-c', 'python /opt/***/dags/apps/crawler.py']
[2023-12-21T14:46:43.494+0000] {subprocess.py:86} INFO - Output:
[2023-12-21T14:46:52.680+0000] {subprocess.py:93} INFO - Traceback (most recent call last):
[2023-12-21T14:46:52.682+0000] {subprocess.py:93} INFO -   File "/opt/***/dags/apps/crawler.py", line 60, in <module>
[2023-12-21T14:46:52.683+0000] {subprocess.py:93} INFO -     driver.execute_script("window.scrollTo(0, document.body.scrollHeight)")
[2023-12-21T14:46:52.687+0000] {subprocess.py:93} INFO -   File "/home/***/.local/lib/python3.8/site-packages/selenium/webdriver/remote/webdriver.py", line 407, in execute_script
[2023-12-21T14:46:52.688+0000] {subprocess.py:93} INFO -     return self.execute(command, {"script": script, "args": converted_args})["value"]
[2023-12-21T14:46:52.690+0000] {subprocess.py:93} INFO -   File "/home/***/.local/lib/python3.8/site-packages/selenium/webdriver/remote/webdriver.py", line 347, in execute
[2023-12-21T14:46:52.692+0000] {subprocess.py:93} INFO -     self.error_handler.check_response(response)
[2023-12-21T14:46:52.693+0000] {subprocess.py:93} INFO -   File "/home/***/.local/lib/python3.8/site-packages/selenium/webdriver/remote/errorhandler.py", line 229, in check_response
[2023-12-21T14:46:52.694+0000] {subprocess.py:93} INFO -     raise exception_class(message, screen, stacktrace)
[2023-12-21T14:46:52.695+0000] {subprocess.py:93} INFO - selenium.common.exceptions.WebDriverException: Message: unknown error: session deleted because of page crash
[2023-12-21T14:46:52.695+0000] {subprocess.py:93} INFO - from unknown error: cannot determine loading status
[2023-12-21T14:46:52.696+0000] {subprocess.py:93} INFO - from tab crashed
[2023-12-21T14:46:52.697+0000] {subprocess.py:93} INFO -   (Session info: headless chrome=117.0.5938.62)
[2023-12-21T14:46:52.698+0000] {subprocess.py:93} INFO - Stacktrace:
[2023-12-21T14:46:52.699+0000] {subprocess.py:93} INFO - #0 0x5630b0c54c07 <unknown>
[2023-12-21T14:46:52.700+0000] {subprocess.py:93} INFO - #1 0x5630b0938d4a <unknown>
[2023-12-21T14:46:52.704+0000] {subprocess.py:93} INFO - #2 0x5630b0924733 <unknown>
[2023-12-21T14:46:52.705+0000] {subprocess.py:93} INFO - #3 0x5630b0923678 <unknown>
[2023-12-21T14:46:52.707+0000] {subprocess.py:93} INFO - #4 0x5630b0923c7d <unknown>
[2023-12-21T14:46:52.710+0000] {subprocess.py:93} INFO - #5 0x5630b0930dd8 <unknown>
[2023-12-21T14:46:52.711+0000] {subprocess.py:93} INFO - #6 0x5630b09439d2 <unknown>
[2023-12-21T14:46:52.712+0000] {subprocess.py:93} INFO - #7 0x5630b09b2680 <unknown>
[2023-12-21T14:46:52.713+0000] {subprocess.py:93} INFO - #8 0x5630b099b9b7 <unknown>
[2023-12-21T14:46:52.714+0000] {subprocess.py:93} INFO - #9 0x5630b0970cad <unknown>
[2023-12-21T14:46:52.715+0000] {subprocess.py:93} INFO - #10 0x5630b0972266 <unknown>
[2023-12-21T14:46:52.716+0000] {subprocess.py:93} INFO - #11 0x5630b0c28c00 <unknown>
[2023-12-21T14:46:52.717+0000] {subprocess.py:93} INFO - #12 0x5630b0c2bdad <unknown>
[2023-12-21T14:46:52.722+0000] {subprocess.py:93} INFO - #13 0x5630b0c2b84a <unknown>
[2023-12-21T14:46:52.724+0000] {subprocess.py:93} INFO - #14 0x5630b0c2c2c9 <unknown>
[2023-12-21T14:46:52.726+0000] {subprocess.py:93} INFO - #15 0x5630b0c327e3 <unknown>
[2023-12-21T14:46:52.727+0000] {subprocess.py:93} INFO - #16 0x5630b0c2c666 <unknown>
[2023-12-21T14:46:52.729+0000] {subprocess.py:93} INFO - #17 0x5630b0c059ea <unknown>
[2023-12-21T14:46:52.730+0000] {subprocess.py:93} INFO - #18 0x5630b0c45689 <unknown>
[2023-12-21T14:46:52.732+0000] {subprocess.py:93} INFO - #19 0x5630b0c4586f <unknown>
[2023-12-21T14:46:52.733+0000] {subprocess.py:93} INFO - #20 0x5630b0c54173 <unknown>
[2023-12-21T14:46:52.738+0000] {subprocess.py:93} INFO - #21 0x7f318c1383ec <unknown>
[2023-12-21T14:46:52.739+0000] {subprocess.py:93} INFO - 
[2023-12-21T14:46:52.740+0000] {subprocess.py:93} INFO - 
[2023-12-21T14:46:52.741+0000] {subprocess.py:93} INFO - During handling of the above exception, another exception occurred:
[2023-12-21T14:46:52.742+0000] {subprocess.py:93} INFO - 
[2023-12-21T14:46:52.743+0000] {subprocess.py:93} INFO - Traceback (most recent call last):
[2023-12-21T14:46:52.744+0000] {subprocess.py:93} INFO -   File "/opt/***/dags/apps/crawler.py", line 78, in <module>
[2023-12-21T14:46:52.745+0000] {subprocess.py:93} INFO -     if driver.find_element(By.XPATH, f'//*[@id="main-content"]/section[2]/button').text == 'Ver mais vagas':
[2023-12-21T14:46:52.746+0000] {subprocess.py:93} INFO -   File "/home/***/.local/lib/python3.8/site-packages/selenium/webdriver/remote/webdriver.py", line 741, in find_element
[2023-12-21T14:46:52.748+0000] {subprocess.py:93} INFO -     return self.execute(Command.FIND_ELEMENT, {"using": by, "value": value})["value"]
[2023-12-21T14:46:52.749+0000] {subprocess.py:93} INFO -   File "/home/***/.local/lib/python3.8/site-packages/selenium/webdriver/remote/webdriver.py", line 347, in execute
[2023-12-21T14:46:52.750+0000] {subprocess.py:93} INFO -     self.error_handler.check_response(response)
[2023-12-21T14:46:52.754+0000] {subprocess.py:93} INFO -   File "/home/***/.local/lib/python3.8/site-packages/selenium/webdriver/remote/errorhandler.py", line 229, in check_response
[2023-12-21T14:46:52.755+0000] {subprocess.py:93} INFO -     raise exception_class(message, screen, stacktrace)
[2023-12-21T14:46:52.757+0000] {subprocess.py:93} INFO - selenium.common.exceptions.InvalidSessionIdException: Message: invalid session id
[2023-12-21T14:46:52.758+0000] {subprocess.py:93} INFO - Stacktrace:
[2023-12-21T14:46:52.759+0000] {subprocess.py:93} INFO - #0 0x5630b0c54c07 <unknown>
[2023-12-21T14:46:52.761+0000] {subprocess.py:93} INFO - #1 0x5630b0938d4a <unknown>
[2023-12-21T14:46:52.762+0000] {subprocess.py:93} INFO - #2 0x5630b097045d <unknown>
[2023-12-21T14:46:52.763+0000] {subprocess.py:93} INFO - #3 0x5630b099bb1a <unknown>
[2023-12-21T14:46:52.763+0000] {subprocess.py:93} INFO - #4 0x5630b0997b67 <unknown>
[2023-12-21T14:46:52.764+0000] {subprocess.py:93} INFO - #5 0x5630b09972a7 <unknown>
[2023-12-21T14:46:52.765+0000] {subprocess.py:93} INFO - #6 0x5630b090b9d7 <unknown>
[2023-12-21T14:46:52.766+0000] {subprocess.py:93} INFO - #7 0x5630b0c28c00 <unknown>
[2023-12-21T14:46:52.766+0000] {subprocess.py:93} INFO - #8 0x5630b0c2bdad <unknown>
[2023-12-21T14:46:52.771+0000] {subprocess.py:93} INFO - #9 0x5630b0c2b84a <unknown>
[2023-12-21T14:46:52.772+0000] {subprocess.py:93} INFO - #10 0x5630b0c2c2c9 <unknown>
[2023-12-21T14:46:52.772+0000] {subprocess.py:93} INFO - #11 0x5630b0c327e3 <unknown>
[2023-12-21T14:46:52.773+0000] {subprocess.py:93} INFO - #12 0x5630b0c2c666 <unknown>
[2023-12-21T14:46:52.774+0000] {subprocess.py:93} INFO - #13 0x5630b0c059ea <unknown>
[2023-12-21T14:46:52.774+0000] {subprocess.py:93} INFO - #14 0x5630b090a28e <unknown>
[2023-12-21T14:46:52.775+0000] {subprocess.py:93} INFO - #15 0x5630b0909a62 <unknown>
[2023-12-21T14:46:52.776+0000] {subprocess.py:93} INFO - #16 0x7f318c0d76ca <unknown>
[2023-12-21T14:46:52.776+0000] {subprocess.py:93} INFO - 
[2023-12-21T14:46:52.777+0000] {subprocess.py:97} INFO - Command exited with return code 1
[2023-12-21T14:46:52.795+0000] {taskinstance.py:1937} ERROR - Task failed with exception
Traceback (most recent call last):
  File "/home/airflow/.local/lib/python3.8/site-packages/airflow/operators/bash.py", line 210, in execute
    raise AirflowException(
airflow.exceptions.AirflowException: Bash command failed. The command returned a non-zero exit code 1.
[2023-12-21T14:46:52.801+0000] {taskinstance.py:1400} INFO - Marking task as FAILED. dag_id=scraping-jobs, task_id=test***, execution_date=20231221T144635, start_date=20231221T144642, end_date=20231221T144652
[2023-12-21T14:46:52.859+0000] {standard_task_runner.py:104} ERROR - Failed to execute job 23 for task test*** (Bash command failed. The command returned a non-zero exit code 1.; 687)
[2023-12-21T14:46:52.883+0000] {local_task_job_runner.py:228} INFO - Task exited with return code 1
[2023-12-21T14:46:52.927+0000] {taskinstance.py:2778} INFO - 0 downstream tasks scheduled from follow-on schedule check
